Workbook
Name Slicer_product: #N/A
Name account: accounts!$A$2:$F$86
Name accounts: accounts!$1:$86
Name deal: pipeline!$E:$E
Name products: products!$A$1:$C$8
Name sales: 'sales teams'!$A$2:$C$36

Sheet pivot table
A1: 1.Number of Deals
A3: Count of opportunity_id
A4: 6117 | B4: =GETPIVOTDATA("opportunity_id",$A$3) -> 6117
A6: 2. Total revenue
A7: Sum of revenue | I7: 15004002
A8: 15004002 | B8: =GETPIVOTDATA("revenue",$A$7) -> 15004002
A11: 3.How is each sales team performing compared to the rest?
A12: Row Labels | B12: Sum of revenue
A13: Cara Losch | B13: 1739327
A14: Corliss Cosme | B14: 569695.77
A15: Garret Kinder | B15: 273585.39
A16: Rosie Papadopoulos | B16: 293414.02
A17: Violet Mclelland | B17: 446568.79
A18: Wilburn Farren | B18: 156063.06
A19: Celia Rouche | B19: 2638097.2
A20: Elease Gluck | B20: 338646.86
A21: Hayden Neloms | B21: 444544.2
A22: Markita Hansen | B22: 636848.2
A23: Rosalina Dieter | B23: 285821.05
A24: Vicki Laflamme | B24: 932236.87
... A48: Zane Levy | B48: 612370.94
A51: 4.Are any sales agents lagging behind?
A52: Row Labels | B52: Sum of revenue
A53: Vicki Laflamme | B53: 932236.87
A54: Kary Hendrixson | B54: 855578.41
A55: Anna Snelling | B55: 776091.45
A56: Kami Bicknell | B56: 724775.96
A57: Markita Hansen | B57: 636848.2
A58: Maureen Marcano | B58: 630663.44
A59: Zane Levy | B59: 612370.94
A60: Darcel Schlecht | B60: 576633.18
A61: Corliss Cosme | B61: 569695.77
A62: Versie Hillebrand | B62: 560647.45
A63: Lajuana Vencill | B63: 551473.89
A64: Jonathan Berthelot | B64: 533099.24
... A82: Wilburn Farren | B82: 156063.06

Sheet pivot table 2
A1: 5.Can you identify any quarter-over-quarter trends?
A2: Row Labels | B2: Sum of revenue
A3: Qtr1 | B3: 1336991.4
A4: Qtr2 | B4: 4265390.8
A5: Qtr3 | B5: 4143151.8
A6: Qtr4 | B6: 4182293.5
A15: 6.Do any products have better win rates?
A16: Count of opportunity_id | B16: Column Labels
A17: Row Labels | B17: Won | C17: Prospecting | D17: Lost | E17: Engaging | F17: Grand Total
A18: GTX Basic | B18: 915 | C18: 29 | D18: 521 | E18: 98 | F18: 1563
A19: MG Special | B19: 793 | C19: 41 | D19: 430 | E19: 95 | F19: 1359
A20: MG Advanced | B20: 654 | C20: 25 | D20: 430 | E20: 72 | F20: 1181
A21: GTX Plus Basic | B21: 653 | C21: 20 | D21: 398 | E21: 97 | F21: 1168
A22: GTX Plus Pro | B22: 479 | C22: 14 | D22: 266 | E22: 55 | F22: 814
A23: GTK 500 | B23: 15 | D23: 10 | E23: 7 | F23: 32
A27: 7. sales by product
A28: Row Labels | B28: Sum of revenue
A29: GTX Basic | B29: 4121351.3
A30: MG Advanced | B30: 3094260.9
A31: GTX Plus Basic | B31: 2911772.2
A32: MG Special | B32: 2731859.3
A33: GTX Plus Pro | B33: 2016191.4
A34: GTK 500 | B34: 128566.87 | K34: 3348224
K35: 2650522.8
K36: 2638097.2
A37: 8.Sales by manager | K37: 2365197.7
A38: Row Labels | B38: Sum of revenue | K38: 2262633.1
A39: Summer Sewald | B39: 3348224 | K39: 1739327
A40: Dustin Brinkmann | B40: 2650522.8
A41: Celia Rouche | B41: 2638097.2
A42: Melvin Marxen | B42: 2365197.7
A43: Rocco Neubert | B43: 2262633.1
A44: Cara Losch | B44: 1739327

Sheet Dashboard

Sheet pipeline
A1: opportunity_id | B1: sales_agent | C1: product | D1: account | E1: deal_stage | F1: engage_date | G1: close_date | H1: close_value | I1: sectors | J1: year_established | K1: revenue | L1: employees | M1: office_location | N1: subsidiary_of | O1: series | P1: sales_price | Q1: manager | R1: regional_office
A2: 1C1I7A6R | B2: Moses Frase | C2: GTX Plus Basic | D2: Cancity | E2: Won | F2: 42663 | G2: 42795 | H2: 1054 | I2: =VLOOKUP(pipeline!D2,account,2,FALSE) -> retail | J2: =VLOOKUP(D2,account,3,FALSE) -> 2001 | K2: =VLOOKUP(D2,account,4,FALSE) -> 718.62 | L2: =VLOOKUP(D2,account,5,FALSE) -> 2448 | M2: =VLOOKUP(D2,account,6,FALSE) -> United States | N2: =VLOOKUP(D2,accounts,7,FALSE) -> 0 | O2: =VLOOKUP(C2,products,2,FALSE) -> GTX | P2: =VLOOKUP(C2,products,3,FALSE) -> 1096 | Q2: =VLOOKUP(B2,sales,2,FALSE) -> Dustin Brinkmann | R2: =VLOOKUP(B2,sales,3,FALSE) -> Central
A3: EC4QE1BX | B3: Darcel Schlecht | C3: MG Special | D3: Cancity | E3: Won | F3: 42668 | G3: 42801 | H3: 50 | I3: =VLOOKUP(pipeline!D3,account,2,FALSE) -> retail | J3: =VLOOKUP(D3,account,3,FALSE) -> 2001 | K3: =VLOOKUP(D3,account,4,FALSE) -> 718.62 | L3: =VLOOKUP(D3,account,5,FALSE) -> 2448 | M3: =VLOOKUP(D3,account,6,FALSE) -> United States | N3: =VLOOKUP(D3,accounts,7,FALSE) -> 0 | O3: =VLOOKUP(C3,products,2,FALSE) -> MG | P3: =VLOOKUP(C3,products,3,FALSE) -> 55 | Q3: =VLOOKUP(B3,sales,2,FALSE) -> Melvin Marxen | R3: =VLOOKUP(B3,sales,3,FALSE) -> Central
A4: MV1LWRNH | B4: Moses Frase | C4: GTX Basic | D4: Codehow | E4: Won | F4: 42668 | G4: 42803 | H4: 588 | I4: =VLOOKUP(pipeline!D4,account,2,FALSE) -> software | J4: =VLOOKUP(D4,account,3,FALSE) -> 1998 | K4: =VLOOKUP(D4,account,4,FALSE) -> 2714.9 | L4: =VLOOKUP(D4,account,5,FALSE) -> 2641 | M4: =VLOOKUP(D4,account,6,FALSE) -> United States | N4: =VLOOKUP(D4,accounts,7,FALSE) -> Acme Corporation | O4: =VLOOKUP(C4,products,2,FALSE) -> GTX | P4: =VLOOKUP(C4,products,3,FALSE) -> 550 | Q4: =VLOOKUP(B4,sales,2,FALSE) -> Dustin Brinkmann | R4: =VLOOKUP(B4,sales,3,FALSE) -> Central
A5: PE84CX4O | B5: Zane Levy | C5: GTX Basic | D5: Hatfan | E5: Won | F5: 42668 | G5: 42796 | H5: 517 | I5: =VLOOKUP(pipeline!D5,account,2,FALSE) -> services | J5: =VLOOKUP(D5,account,3,FALSE) -> 1982 | K5: =VLOOKUP(D5,account,4,FALSE) -> 792.46 | L5: =VLOOKUP(D5,account,5,FALSE) -> 1299 | M5: =VLOOKUP(D5,account,6,FALSE) -> United States | N5: =VLOOKUP(D5,accounts,7,FALSE) -> 0 | O5: =VLOOKUP(C5,products,2,FALSE) -> GTX | P5: =VLOOKUP(C5,products,3,FALSE) -> 550 | Q5: =VLOOKUP(B5,sales,2,FALSE) -> Summer Sewald | R5: =VLOOKUP(B5,sales,3,FALSE) -> West
A6: ZNBS69V1 | B6: Anna Snelling | C6: MG Special | D6: Ron-tech | E6: Won | F6: 42672 | G6: 42795 | H6: 49 | I6: =VLOOKUP(pipeline!D6,account,2,FALSE) -> medical | J6: =VLOOKUP(D6,account,3,FALSE) -> 1992 | K6: =VLOOKUP(D6,account,4,FALSE) -> 3922.42 | L6: =VLOOKUP(D6,account,5,FALSE) -> 6837 | M6: =VLOOKUP(D6,account,6,FALSE) -> United States | N6: =VLOOKUP(D6,accounts,7,FALSE) -> 0 | O6: =VLOOKUP(C6,products,2,FALSE) -> MG | P6: =VLOOKUP(C6,products,3,FALSE) -> 55 | Q6: =VLOOKUP(B6,sales,2,FALSE) -> Dustin Brinkmann | R6: =VLOOKUP(B6,sales,3,FALSE) -> Central
A7: 9ME3374G | B7: Vicki Laflamme | C7: MG Special | D7: J-Texon | E7: Won | F7: 42673 | G7: 42796 | H7: 57 | I7: =VLOOKUP(pipeline!D7,account,2,FALSE) -> retail | J7: =VLOOKUP(D7,account,3,FALSE) -> 1989 | K7: =VLOOKUP(D7,account,4,FALSE) -> 1388.67 | L7: =VLOOKUP(D7,account,5,FALSE) -> 3583 | M7: =VLOOKUP(D7,account,6,FALSE) -> United States | N7: =VLOOKUP(D7,accounts,7,FALSE) -> 0 | O7: =VLOOKUP(C7,products,2,FALSE) -> MG | P7: =VLOOKUP(C7,products,3,FALSE) -> 55 | Q7: =VLOOKUP(B7,sales,2,FALSE) -> Celia Rouche | R7: =VLOOKUP(B7,sales,3,FALSE) -> West
A8: 7GN8Q4LL | B8: Markita Hansen | C8: GTX Basic | D8: Cheers | E8: Won | F8: 42675 | G8: 42801 | H8: 601 | I8: =VLOOKUP(pipeline!D8,account,2,FALSE) -> entertainment | J8: =VLOOKUP(D8,account,3,FALSE) -> 1993 | K8: =VLOOKUP(D8,account,4,FALSE) -> 4269.9 | L8: =VLOOKUP(D8,account,5,FALSE) -> 6472 | M8: =VLOOKUP(D8,account,6,FALSE) -> United States | N8: =VLOOKUP(D8,accounts,7,FALSE) -> Massive Dynamic | O8: =VLOOKUP(C8,products,2,FALSE) -> GTX | P8: =VLOOKUP(C8,products,3,FALSE) -> 550 | Q8: =VLOOKUP(B8,sales,2,FALSE) -> Celia Rouche | R8: =VLOOKUP(B8,sales,3,FALSE) -> West
A9: OLK9LKZB | B9: Niesha Huffines | C9: GTX Plus Basic | D9: Zumgoity | E9: Won | F9: 42675 | G9: 42797 | H9: 1026 | I9: =VLOOKUP(pipeline!D9,account,2,FALSE) -> medical | J9: =VLOOKUP(D9,account,3,FALSE) -> 1984 | K9: =VLOOKUP(D9,account,4,FALSE) -> 441.08 | L9: =VLOOKUP(D9,account,5,FALSE) -> 1210 | M9: =VLOOKUP(D9,account,6,FALSE) -> United States | N9: =VLOOKUP(D9,accounts,7,FALSE) -> 0 | O9: =VLOOKUP(C9,products,2,FALSE) -> GTX | P9: =VLOOKUP(C9,products,3,FALSE) -> 1096 | Q9: =VLOOKUP(B9,sales,2,FALSE) -> Melvin Marxen | R9: =VLOOKUP(B9,sales,3,FALSE) -> Central
A10: NL3JZH1Z | B10: Anna Snelling | C10: MG Special | D10: Bioholding | E10: Won | F10: 42678 | G10: 42804 | H10: 53 | I10: =VLOOKUP(pipeline!D10,account,2,FALSE) -> medical | J10: =VLOOKUP(D10,account,3,FALSE) -> 2012 | K10: =VLOOKUP(D10,account,4,FALSE) -> 587.34 | L10: =VLOOKUP(D10,account,5,FALSE) -> 1356 | M10: =VLOOKUP(D10,account,6,FALSE) -> Philipines | N10: =VLOOKUP(D10,accounts,7,FALSE) -> 0 | O10: =VLOOKUP(C10,products,2,FALSE) -> MG | P10: =VLOOKUP(C10,products,3,FALSE) -> 55 | Q10: =VLOOKUP(B10,sales,2,FALSE) -> Dustin Brinkmann | R10: =VLOOKUP(B10,sales,3,FALSE) -> Central
A11: S8DX3XOU | B11: James Ascencio | C11: GTX Plus Pro | D11: Sunnamplex | E11: Won | F11: 42678 | G11: 42804 | H11: 5169 | I11: =VLOOKUP(pipeline!D11,account,2,FALSE) -> marketing | J11: =VLOOKUP(D11,account,3,FALSE) -> 2008 | K11: =VLOOKUP(D11,account,4,FALSE) -> 894.37 | L11: =VLOOKUP(D11,account,5,FALSE) -> 1593 | M11: =VLOOKUP(D11,account,6,FALSE) -> Poland | N11: =VLOOKUP(D11,accounts,7,FALSE) -> 0 | O11: =VLOOKUP(C11,products,2,FALSE) -> GTX | P11: =VLOOKUP(C11,products,3,FALSE) -> 5482 | Q11: =VLOOKUP(B11,sales,2,FALSE) -> Summer Sewald | R11: =VLOOKUP(B11,sales,3,FALSE) -> West
A12: ENB2XD8G | B12: Maureen Marcano | C12: GTX Plus Pro | D12: Sonron | E12: Won | F12: 42678 | G12: 42800 | H12: 4631 | I12: =VLOOKUP(pipeline!D12,account,2,FALSE) -> telecommunications | J12: =VLOOKUP(D12,account,3,FALSE) -> 1999 | K12: =VLOOKUP(D12,account,4,FALSE) -> 1699.85 | L12: =VLOOKUP(D12,account,5,FALSE) -> 5108 | M12: =VLOOKUP(D12,account,6,FALSE) -> United States | N12: =VLOOKUP(D12,accounts,7,FALSE) -> 0 | O12: =VLOOKUP(C12,products,2,FALSE) -> GTX | P12: =VLOOKUP(C12,products,3,FALSE) -> 5482 | Q12: =VLOOKUP(B12,sales,2,FALSE) -> Summer Sewald | R12: =VLOOKUP(B12,sales,3,FALSE) -> West
A13: 09YE9QOV | B13: Hayden Neloms | C13: MG Advanced | D13: Finjob | E13: Won | F13: 42679 | G13: 42805 | H13: 3393 | I13: =VLOOKUP(pipeline!D13,account,2,FALSE) -> employment | J13: =VLOOKUP(D13,account,3,FALSE) -> 1988 | K13: =VLOOKUP(D13,account,4,FALSE) -> 2059.9 | L13: =VLOOKUP(D13,account,5,FALSE) -> 3644 | M13: =VLOOKUP(D13,account,6,FALSE) -> United States | N13: =VLOOKUP(D13,accounts,7,FALSE) -> 0 | O13: =VLOOKUP(C13,products,2,FALSE) -> MG | P13: =VLOOKUP(C13,products,3,FALSE) -> 3393 | Q13: =VLOOKUP(B13,sales,2,FALSE) -> Celia Rouche | R13: =VLOOKUP(B13,sales,3,FALSE) -> West
... A22: SBCR987L | B22: Kami Bicknell | C22: GTX Basic | D22: Zoomit | E22: Won | F22: 42684 | G22: 42817 | H22: 590 | I22: =VLOOKUP(pipeline!D22,account,2,FALSE) -> entertainment | J22: =VLOOKUP(D22,account,3,FALSE) -> 1992 | K22: =VLOOKUP(D22,account,4,FALSE) -> 324.19 | L22: =VLOOKUP(D22,account,5,FALSE) -> 978 | M22: =VLOOKUP(D22,account,6,FALSE) -> United States | N22: =VLOOKUP(D22,accounts,7,FALSE) -> 0 | O22: =VLOOKUP(C22,products,2,FALSE) -> GTX | P22: =VLOOKUP(C22,products,3,FALSE) -> 550 | Q22: =VLOOKUP(B22,sales,2,FALSE) -> Summer Sewald | R22: =VLOOKUP(B22,sales,3,FALSE) -> West
A23: UP409DSB | B23: Maureen Marcano | C23: MG Advanced | D23: Ganjaflex | E23: Engaging | F23: 42684 | I23: =VLOOKUP(pipeline!D23,account,2,FALSE) -> retail | J23: =VLOOKUP(D23,account,3,FALSE) -> 1995 | K23: =VLOOKUP(D23,account,4,FALSE) -> 5158.71 | L23: =VLOOKUP(D23,account,5,FALSE) -> 17479 | M23: =VLOOKUP(D23,account,6,FALSE) -> Japan | N23: =VLOOKUP(D23,accounts,7,FALSE) -> 0 | O23: =VLOOKUP(C23,products,2,FALSE) -> MG | P23: =VLOOKUP(C23,products,3,FALSE) -> 3393 | Q23: =VLOOKUP(B23,sales,2,FALSE) -> Summer Sewald | R23: =VLOOKUP(B23,sales,3,FALSE) -> West
A24: JSD4APT2 | B24: Versie Hillebrand | C24: MG Special | D24: Bioholding | E24: Won | F24: 42684 | G24: 42806 | H24: 61 | I24: =VLOOKUP(pipeline!D24,account,2,FALSE) -> medical | J24: =VLOOKUP(D24,account,3,FALSE) -> 2012 | K24: =VLOOKUP(D24,account,4,FALSE) -> 587.34 | L24: =VLOOKUP(D24,account,5,FALSE) -> 1356 | M24: =VLOOKUP(D24,account,6,FALSE) -> Philipines | N24: =VLOOKUP(D24,accounts,7,FALSE) -> 0 | O24: =VLOOKUP(C24,products,2,FALSE) -> MG | P24: =VLOOKUP(C24,products,3,FALSE) -> 55 | Q24: =VLOOKUP(B24,sales,2,FALSE) -> Dustin Brinkmann | R24: =VLOOKUP(B24,sales,3,FALSE) -> Central
A25: AO9Z2D17 | B25: Violet Mclelland | C25: GTX Plus Pro | D25: Xx-zobam | E25: Lost | F25: 42684 | G25: 42805 | H25: 0 | I25: =VLOOKUP(pipeline!D25,account,2,FALSE) -> entertainment | J25: =VLOOKUP(D25,account,3,FALSE) -> 1989 | K25: =VLOOKUP(D25,account,4,FALSE) -> 3838.39 | L25: =VLOOKUP(D25,account,5,FALSE) -> 8274 | M25: =VLOOKUP(D25,account,6,FALSE) -> United States | N25: =VLOOKUP(D25,accounts,7,FALSE) -> 0 | O25: =VLOOKUP(C25,products,2,FALSE) -> GTX | P25: =VLOOKUP(C25,products,3,FALSE) -> 5482 | Q25: =VLOOKUP(B25,sales,2,FALSE) -> Cara Losch | R25: =VLOOKUP(B25,sales,3,FALSE) -> East
A26: 5M58DTJK | B26: Elease Gluck | C26: MG Special | D26: Cheers | E26: Won | F26: 42685 | G26: 42799 | H26: 58 | I26: =VLOOKUP(pipeline!D26,account,2,FALSE) -> entertainment | J26: =VLOOKUP(D26,account,3,FALSE) -> 1993 | K26: =VLOOKUP(D26,account,4,FALSE) -> 4269.9 | L26: =VLOOKUP(D26,account,5,FALSE) -> 6472 | M26: =VLOOKUP(D26,account,6,FALSE) -> United States | N26: =VLOOKUP(D26,accounts,7,FALSE) -> Massive Dynamic | O26: =VLOOKUP(C26,products,2,FALSE) -> MG | P26: =VLOOKUP(C26,products,3,FALSE) -> 55 | Q26: =VLOOKUP(B26,sales,2,FALSE) -> Celia Rouche | R26: =VLOOKUP(B26,sales,3,FALSE) -> West
A27: EAZDUUM9 | B27: Rosie Papadopoulos | C27: MG Advanced | D27: Zotware | E27: Lost | F27: 42685 | G27: 42795 | H27: 0 | I27: =VLOOKUP(pipeline!D27,account,2,FALSE) -> software | J27: =VLOOKUP(D27,account,3,FALSE) -> 1979 | K27: =VLOOKUP(D27,account,4,FALSE) -> 4478.47 | L27: =VLOOKUP(D27,account,5,FALSE) -> 13809 | M27: =VLOOKUP(D27,account,6,FALSE) -> United States | N27: =VLOOKUP(D27,accounts,7,FALSE) -> 0 | O27: =VLOOKUP(C27,products,2,FALSE) -> MG | P27: =VLOOKUP(C27,products,3,FALSE) -> 3393 | Q27: =VLOOKUP(B27,sales,2,FALSE) -> Cara Losch | R27: =VLOOKUP(B27,sales,3,FALSE) -> East
A28: 2STUSOFE | B28: Versie Hillebrand | C28: MG Special | D28: dambase | E28: Won | F28: 42685 | G28: 42797 | H28: 67 | I28: =VLOOKUP(pipeline!D28,account,2,FALSE) -> marketing | J28: =VLOOKUP(D28,account,3,FALSE) -> 1995 | K28: =VLOOKUP(D28,account,4,FALSE) -> 2173.98 | L28: =VLOOKUP(D28,account,5,FALSE) -> 2928 | M28: =VLOOKUP(D28,account,6,FALSE) -> United States | N28: =VLOOKUP(D28,accounts,7,FALSE) -> Inity | O28: =VLOOKUP(C28,products,2,FALSE) -> MG | P28: =VLOOKUP(C28,products,3,FALSE) -> 55 | Q28: =VLOOKUP(B28,sales,2,FALSE) -> Dustin Brinkmann | R28: =VLOOKUP(B28,sales,3,FALSE) -> Central
A29: KU28360J | B29: Kary Hendrixson | C29: GTX Basic | D29: Fasehatice | E29: Won | F29: 42686 | G29: 42813 | H29: 578 | I29: =VLOOKUP(pipeline!D29,account,2,FALSE) -> retail | J29: =VLOOKUP(D29,account,3,FALSE) -> 1990 | K29: =VLOOKUP(D29,account,4,FALSE) -> 4968.91 | L29: =VLOOKUP(D29,account,5,FALSE) -> 7523 | M29: =VLOOKUP(D29,account,6,FALSE) -> United States | N29: =VLOOKUP(D29,accounts,7,FALSE) -> 0 | O29: =VLOOKUP(C29,products,2,FALSE) -> GTX | P29: =VLOOKUP(C29,products,3,FALSE) -> 550 | Q29: =VLOOKUP(B29,sales,2,FALSE) -> Summer Sewald | R29: =VLOOKUP(B29,sales,3,FALSE) -> West
A30: N4SD17JR | B30: Reed Clapper | C30: GTX Basic | D30: Acme Corporation | E30: Won | F30: 42686 | G30: 42795 | H30: 556 | I30: =VLOOKUP(pipeline!D30,account,2,FALSE) -> technolgy | J30: =VLOOKUP(D30,account,3,FALSE) -> 1996 | K30: =VLOOKUP(D30,account,4,FALSE) -> 1100.04 | L30: =VLOOKUP(D30,account,5,FALSE) -> 2822 | M30: =VLOOKUP(D30,account,6,FALSE) -> United States | N30: =VLOOKUP(D30,accounts,7,FALSE) -> 0 | O30: =VLOOKUP(C30,products,2,FALSE) -> GTX | P30: =VLOOKUP(C30,products,3,FALSE) -> 550 | Q30: =VLOOKUP(B30,sales,2,FALSE) -> Rocco Neubert | R30: =VLOOKUP(B30,sales,3,FALSE) -> East
A31: E67P9Y3Q | B31: Rosalina Dieter | C31: GTX Basic | D31: Green-Plus | E31: Won | F31: 42686 | G31: 42797 | H31: 635 | I31: =VLOOKUP(pipeline!D31,account,2,FALSE) -> services | J31: =VLOOKUP(D31,account,3,FALSE) -> 2003 | K31: =VLOOKUP(D31,account,4,FALSE) -> 692.19 | L31: =VLOOKUP(D31,account,5,FALSE) -> 1922 | M31: =VLOOKUP(D31,account,6,FALSE) -> United States | N31: =VLOOKUP(D31,accounts,7,FALSE) -> 0 | O31: =VLOOKUP(C31,products,2,FALSE) -> GTX | P31: =VLOOKUP(C31,products,3,FALSE) -> 550 | Q31: =VLOOKUP(B31,sales,2,FALSE) -> Celia Rouche | R31: =VLOOKUP(B31,sales,3,FALSE) -> West
A32: AT3MMVIS | B32: Wilburn Farren | C32: MG Advanced | D32: The New York Inquirer | E32: Won | F32: 42686 | G32: 42801 | H32: 3045 | I32: =VLOOKUP(pipeline!D32,account,2,FALSE) -> medical | J32: =VLOOKUP(D32,account,3,FALSE) -> 1996 | K32: =VLOOKUP(D32,account,4,FALSE) -> 439.21 | L32: =VLOOKUP(D32,account,5,FALSE) -> 792 | M32: =VLOOKUP(D32,account,6,FALSE) -> United States | N32: =VLOOKUP(D32,accounts,7,FALSE) -> 0 | O32: =VLOOKUP(C32,products,2,FALSE) -> MG | P32: =VLOOKUP(C32,products,3,FALSE) -> 3393 | Q32: =VLOOKUP(B32,sales,2,FALSE) -> Cara Losch | R32: =VLOOKUP(B32,sales,3,FALSE) -> East
A33: REJ11LRY | B33: Garret Kinder | C33: GTX Plus Basic | D33: Mathtouch | E33: Won | F33: 42687 | G33: 42808 | H33: 1233 | I33: =VLOOKUP(pipeline!D33,account,2,FALSE) -> marketing | J33: =VLOOKUP(D33,account,3,FALSE) -> 1984 | K33: =VLOOKUP(D33,account,4,FALSE) -> 3027.46 | L33: =VLOOKUP(D33,account,5,FALSE) -> 9516 | M33: =VLOOKUP(D33,account,6,FALSE) -> Jordan | N33: =VLOOKUP(D33,accounts,7,FALSE) -> 0 | O33: =VLOOKUP(C33,products,2,FALSE) -> GTX | P33: =VLOOKUP(C33,products,3,FALSE) -> 1096 | Q33: =VLOOKUP(B33,sales,2,FALSE) -> Cara Losch | R33: =VLOOKUP(B33,sales,3,FALSE) -> East
A34: ERV0CAZ7 | B34: Versie Hillebrand | C34: MG Special | D34: Zumgoity | E34: Won | F34: 42687 | G34: 42803 | H34: 60 | I34: =VLOOKUP(pipeline!D34,account,2,FALSE) -> medical | J34: =VLOOKUP(D34,account,3,FALSE) -> 1984 | K34: =VLOOKUP(D34,account,4,FALSE) -> 441.08 | L34: =VLOOKUP(D34,account,5,FALSE) -> 1210 | M34: =VLOOKUP(D34,account,6,FALSE) -> United States | N34: =VLOOKUP(D34,accounts,7,FALSE) -> 0 | O34: =VLOOKUP(C34,products,2,FALSE) -> MG | P34: =VLOOKUP(C34,products,3,FALSE) -> 55 | Q34: =VLOOKUP(B34,sales,2,FALSE) -> Dustin Brinkmann | R34: =VLOOKUP(B34,sales,3,FALSE) -> Central
A35: 8SOQADK7 | B35: Anna Snelling | C35: MG Special | D35: Gogozoom | E35: Lost | F35: 42688 | G35: 42824 | H35: 0 | I35: =VLOOKUP(pipeline!D35,account,2,FALSE) -> telecommunications | J35: =VLOOKUP(D35,account,3,FALSE) -> 2007 | K35: =VLOOKUP(D35,account,4,FALSE) -> 86.68 | L35: =VLOOKUP(D35,account,5,FALSE) -> 187 | M35: =VLOOKUP(D35,account,6,FALSE) -> United States | N35: =VLOOKUP(D35,accounts,7,FALSE) -> Sonron | O35: =VLOOKUP(C35,products,2,FALSE) -> MG | P35: =VLOOKUP(C35,products,3,FALSE) -> 55 | Q35: =VLOOKUP(B35,sales,2,FALSE) -> Dustin Brinkmann | R35: =VLOOKUP(B35,sales,3,FALSE) -> Central
... A53: MYDUMR3R | B53: Lajuana Vencill | C53: GTX Basic | D53: Rangreen | E53: Won | F53: 42694 | G53: 42798 | H53: 559 | I53: =VLOOKUP(pipeline!D53,account,2,FALSE) -> technolgy | J53: =VLOOKUP(D53,account,3,FALSE) -> 1987 | K53: =VLOOKUP(D53,account,4,FALSE) -> 2938.67 | L53: =VLOOKUP(D53,account,5,FALSE) -> 8775 | M53: =VLOOKUP(D53,account,6,FALSE) -> Panama | N53: =VLOOKUP(D53,accounts,7,FALSE) -> 0 | O53: =VLOOKUP(C53,products,2,FALSE) -> GTX | P53: =VLOOKUP(C53,products,3,FALSE) -> 550 | Q53: =VLOOKUP(B53,sales,2,FALSE) -> Dustin Brinkmann | R53: =VLOOKUP(B53,sales,3,FALSE) -> Central
A54: 0DRC1U9Q | B54: Maureen Marcano | C54: GTX Basic | D54: Green-Plus | E54: Engaging | F54: 42694 | I54: =VLOOKUP(pipeline!D54,account,2,FALSE) -> services | J54: =VLOOKUP(D54,account,3,FALSE) -> 2003 | K54: =VLOOKUP(D54,account,4,FALSE) -> 692.19 | L54: =VLOOKUP(D54,account,5,FALSE) -> 1922 | M54: =VLOOKUP(D54,account,6,FALSE) -> United States | N54: =VLOOKUP(D54,accounts,7,FALSE) -> 0 | O54: =VLOOKUP(C54,products,2,FALSE) -> GTX | P54: =VLOOKUP(C54,products,3,FALSE) -> 550 | Q54: =VLOOKUP(B54,sales,2,FALSE) -> Summer Sewald | R54: =VLOOKUP(B54,sales,3,FALSE) -> West
A55: 37JFKD4I | B55: Niesha Huffines | C55: GTX Plus Basic | D55: dambase | E55: Won | F55: 42694 | G55: 42803 | H55: 1033 | I55: =VLOOKUP(pipeline!D55,account,2,FALSE) -> marketing | J55: =VLOOKUP(D55,account,3,FALSE) -> 1995 | K55: =VLOOKUP(D55,account,4,FALSE) -> 2173.98 | L55: =VLOOKUP(D55,account,5,FALSE) -> 2928 | M55: =VLOOKUP(D55,account,6,FALSE) -> United States | N55: =VLOOKUP(D55,accounts,7,FALSE) -> Inity | O55: =VLOOKUP(C55,products,2,FALSE) -> GTX | P55: =VLOOKUP(C55,products,3,FALSE) -> 1096 | Q55: =VLOOKUP(B55,sales,2,FALSE) -> Melvin Marxen | R55: =VLOOKUP(B55,sales,3,FALSE) -> Central
A56: 25YKPHX8 | B56: Donn Cantrell | C56: GTX Basic | D56: Kan-code | E56: Won | F56: 42695 | G56: 42815 | H56: 462 | I56: =VLOOKUP(pipeline!D56,account,2,FALSE) -> software | J56: =VLOOKUP(D56,account,3,FALSE) -> 1982 | K56: =VLOOKUP(D56,account,4,FALSE) -> 11698.03 | L56: =VLOOKUP(D56,account,5,FALSE) -> 34288 | M56: =VLOOKUP(D56,account,6,FALSE) -> United States | N56: =VLOOKUP(D56,accounts,7,FALSE) -> 0 | O56: =VLOOKUP(C56,products,2,FALSE) -> GTX | P56: =VLOOKUP(C56,products,3,FALSE) -> 550 | Q56: =VLOOKUP(B56,sales,2,FALSE) -> Rocco Neubert | R56: =VLOOKUP(B56,sales,3,FALSE) -> East
A57: BXXMA7F3 | B57: Hayden Neloms | C57: MG Advanced | D57: Nam-zim | E57: Lost | F57: 42695 | G57: 42795 | H57: 0 | I57: =VLOOKUP(pipeline!D57,account,2,FALSE) -> services | J57: =VLOOKUP(D57,account,3,FALSE) -> 1987 | K57: =VLOOKUP(D57,account,4,FALSE) -> 405.59 | L57: =VLOOKUP(D57,account,5,FALSE) -> 1179 | M57: =VLOOKUP(D57,account,6,FALSE) -> Brazil | N57: =VLOOKUP(D57,accounts,7,FALSE) -> Warephase | O57: =VLOOKUP(C57,products,2,FALSE) -> MG | P57: =VLOOKUP(C57,products,3,FALSE) -> 3393 | Q57: =VLOOKUP(B57,sales,2,FALSE) -> Celia Rouche | R57: =VLOOKUP(B57,sales,3,FALSE) -> West
A58: MFX2LR1Q | B58: Lajuana Vencill | C58: MG Advanced | D58: Ron-tech | E58: Won | F58: 42695 | G58: 42809 | H58: 3573 | I58: =VLOOKUP(pipeline!D58,account,2,FALSE) -> medical | J58: =VLOOKUP(D58,account,3,FALSE) -> 1992 | K58: =VLOOKUP(D58,account,4,FALSE) -> 3922.42 | L58: =VLOOKUP(D58,account,5,FALSE) -> 6837 | M58: =VLOOKUP(D58,account,6,FALSE) -> United States | N58: =VLOOKUP(D58,accounts,7,FALSE) -> 0 | O58: =VLOOKUP(C58,products,2,FALSE) -> MG | P58: =VLOOKUP(C58,products,3,FALSE) -> 3393 | Q58: =VLOOKUP(B58,sales,2,FALSE) -> Dustin Brinkmann | R58: =VLOOKUP(B58,sales,3,FALSE) -> Central
A59: 96BSG7R1 | B59: Zane Levy | C59: GTX Plus Basic | D59: Sunnamplex | E59: Lost | F59: 42695 | G59: 42811 | H59: 0 | I59: =VLOOKUP(pipeline!D59,account,2,FALSE) -> marketing | J59: =VLOOKUP(D59,account,3,FALSE) -> 2008 | K59: =VLOOKUP(D59,account,4,FALSE) -> 894.37 | L59: =VLOOKUP(D59,account,5,FALSE) -> 1593 | M59: =VLOOKUP(D59,account,6,FALSE) -> Poland | N59: =VLOOKUP(D59,accounts,7,FALSE) -> 0 | O59: =VLOOKUP(C59,products,2,FALSE) -> GTX | P59: =VLOOKUP(C59,products,3,FALSE) -> 1096 | Q59: =VLOOKUP(B59,sales,2,FALSE) -> Summer Sewald | R59: =VLOOKUP(B59,sales,3,FALSE) -> West
A60: 7FQMSWIX | B60: Corliss Cosme | C60: MG Special | D60: Bioplex | E60: Won | F60: 42696 | G60: 42798 | H60: 62 | I60: =VLOOKUP(pipeline!D60,account,2,FALSE) -> medical | J60: =VLOOKUP(D60,account,3,FALSE) -> 1991 | K60: =VLOOKUP(D60,account,4,FALSE) -> 326.82 | L60: =VLOOKUP(D60,account,5,FALSE) -> 1016 | M60: =VLOOKUP(D60,account,6,FALSE) -> United States | N60: =VLOOKUP(D60,accounts,7,FALSE) -> 0 | O60: =VLOOKUP(C60,products,2,FALSE) -> MG | P60: =VLOOKUP(C60,products,3,FALSE) -> 55 | Q60: =VLOOKUP(B60,sales,2,FALSE) -> Cara Losch | R60: =VLOOKUP(B60,sales,3,FALSE) -> East
A61: GS1QVWCR | B61: Kami Bicknell | C61: GTX Basic | D61: Plusstrip | E61: Won | F61: 42696 | G61: 42825 | H61: 566 | I61: =VLOOKUP(pipeline!D61,account,2,FALSE) -> entertainment | J61: =VLOOKUP(D61,account,3,FALSE) -> 2002 | K61: =VLOOKUP(D61,account,4,FALSE) -> 349.81 | L61: =VLOOKUP(D61,account,5,FALSE) -> 315 | M61: =VLOOKUP(D61,account,6,FALSE) -> United States | N61: =VLOOKUP(D61,accounts,7,FALSE) -> 0 | O61: =VLOOKUP(C61,products,2,FALSE) -> GTX | P61: =VLOOKUP(C61,products,3,FALSE) -> 550 | Q61: =VLOOKUP(B61,sales,2,FALSE) -> Summer Sewald | R61: =VLOOKUP(B61,sales,3,FALSE) -> West
A62: ZWH8FXY3 | B62: Marty Freudenburg | C62: GTX Basic | D62: Toughzap | E62: Won | F62: 42696 | G62: 42797 | H62: 508 | I62: =VLOOKUP(pipeline!D62,account,2,FALSE) -> retail | J62: =VLOOKUP(D62,account,3,FALSE) -> 1995 | K62: =VLOOKUP(D62,account,4,FALSE) -> 332.43 | L62: =VLOOKUP(D62,account,5,FALSE) -> 799 | M62: =VLOOKUP(D62,account,6,FALSE) -> United States | N62: =VLOOKUP(D62,accounts,7,FALSE) -> 0 | O62: =VLOOKUP(C62,products,2,FALSE) -> GTX | P62: =VLOOKUP(C62,products,3,FALSE) -> 550 | Q62: =VLOOKUP(B62,sales,2,FALSE) -> Melvin Marxen | R62: =VLOOKUP(B62,sales,3,FALSE) -> Central
A63: 2U94Y3Q9 | B63: Rosie Papadopoulos | C63: MG Advanced | D63: Vehement Capital Partners | E63: Lost | F63: 42696 | G63: 42814 | H63: 0 | I63: =VLOOKUP(pipeline!D63,account,2,FALSE) -> finance | J63: =VLOOKUP(D63,account,3,FALSE) -> 1993 | K63: =VLOOKUP(D63,account,4,FALSE) -> 646.1 | L63: =VLOOKUP(D63,account,5,FALSE) -> 883 | M63: =VLOOKUP(D63,account,6,FALSE) -> United States | N63: =VLOOKUP(D63,accounts,7,FALSE) -> Golddex | O63: =VLOOKUP(C63,products,2,FALSE) -> MG | P63: =VLOOKUP(C63,products,3,FALSE) -> 3393 | Q63: =VLOOKUP(B63,sales,2,FALSE) -> Cara Losch | R63: =VLOOKUP(B63,sales,3,FALSE) -> East
A64: AAR79NOO | B64: Versie Hillebrand | C64: MG Special | D64: Codehow | E64: Won | F64: 42696 | G64: 42805 | H64: 51 | I64: =VLOOKUP(pipeline!D64,account,2,FALSE) -> software | J64: =VLOOKUP(D64,account,3,FALSE) -> 1998 | K64: =VLOOKUP(D64,account,4,FALSE) -> 2714.9 | L64: =VLOOKUP(D64,account,5,FALSE) -> 2641 | M64: =VLOOKUP(D64,account,6,FALSE) -> United States | N64: =VLOOKUP(D64,accounts,7,FALSE) -> Acme Corporation | O64: =VLOOKUP(C64,products,2,FALSE) -> MG | P64: =VLOOKUP(C64,products,3,FALSE) -> 55 | Q64: =VLOOKUP(B64,sales,2,FALSE) -> Dustin Brinkmann | R64: =VLOOKUP(B64,sales,3,FALSE) -> Central
A65: M7I5O9YU | B65: Corliss Cosme | C65: GTX Basic | D65: Cheers | E65: Engaging | F65: 42697 | I65: =VLOOKUP(pipeline!D65,account,2,FALSE) -> entertainment | J65: =VLOOKUP(D65,account,3,FALSE) -> 1993 | K65: =VLOOKUP(D65,account,4,FALSE) -> 4269.9 | L65: =VLOOKUP(D65,account,5,FALSE) -> 6472 | M65: =VLOOKUP(D65,account,6,FALSE) -> United States | N65: =VLOOKUP(D65,accounts,7,FALSE) -> Massive Dynamic | O65: =VLOOKUP(C65,products,2,FALSE) -> GTX | P65: =VLOOKUP(C65,products,3,FALSE) -> 550 | Q65: =VLOOKUP(B65,sales,2,FALSE) -> Cara Losch | R65: =VLOOKUP(B65,sales,3,FALSE) -> East
...

Sheet accounts
A1: account | B1: sector | C1: year_established | D1: revenue | E1: employees | F1: office_location | G1: subsidiary_of
A2: Acme Corporation | B2: technolgy | C2: 1996 | D2: 1100.04 | E2: 2822 | F2: United States
A3: Betasoloin | B3: medical | C3: 1999 | D3: 251.41 | E3: 495 | F3: United States
A4: Betatech | B4: medical | C4: 1986 | D4: 647.18 | E4: 1185 | F4: Kenya
A5: Bioholding | B5: medical | C5: 2012 | D5: 587.34 | E5: 1356 | F5: Philipines
A6: Bioplex | B6: medical | C6: 1991 | D6: 326.82 | E6: 1016 | F6: United States
A7: Blackzim | B7: retail | C7: 2009 | D7: 497.11 | E7: 1588 | F7: United States
A8: Bluth Company | B8: technolgy | C8: 1993 | D8: 1242.32 | E8: 3027 | F8: United States | G8: Acme Corporation
A9: Bubba Gump | B9: software | C9: 2002 | D9: 987.39 | E9: 2253 | F9: United States
A10: Cancity | B10: retail | C10: 2001 | D10: 718.62 | E10: 2448 | F10: United States
A11: Cheers | B11: entertainment | C11: 1993 | D11: 4269.9 | E11: 6472 | F11: United States | G11: Massive Dynamic
A12: Codehow | B12: software | C12: 1998 | D12: 2714.9 | E12: 2641 | F12: United States | G12: Acme Corporation
A13: Condax | B13: medical | C13: 2017 | D13: 4.54 | E13: 9 | F13: United States
A14: Conecom | B14: technolgy | C14: 2005 | D14: 1520.66 | E14: 1806 | F14: United States
A15: Dalttechnology | B15: software | C15: 2013 | D15: 98.79 | E15: 96 | F15: United States | G15: Bubba Gump
A16: dambase | B16: marketing | C16: 1995 | D16: 2173.98 | E16: 2928 | F16: United States | G16: Inity
A17: Domzoom | B17: entertainment | C17: 1998 | D17: 217.87 | E17: 551 | F17: United States
A18: Doncon | B18: technolgy | C18: 2010 | D18: 587.72 | E18: 1501 | F18: United States
A19: Donquadtech | B19: technolgy | C19: 1992 | D19: 1712.68 | E19: 3194 | F19: United States | G19: Acme Corporation
A20: Dontechi | B20: software | C20: 1982 | D20: 4618 | E20: 10083 | F20: United States
A21: Donware | B21: marketing | C21: 1999 | D21: 1197.44 | E21: 2570 | F21: United States
A22: Fasehatice | B22: retail | C22: 1990 | D22: 4968.91 | E22: 7523 | F22: United States
A23: Faxquote | B23: telecommunications | C23: 1995 | D23: 1825.82 | E23: 5595 | F23: United States | G23: Sonron
A24: Finhigh | B24: finance | C24: 2006 | D24: 1102.43 | E24: 1759 | F24: United States
A25: Finjob | B25: employment | C25: 1988 | D25: 2059.9 | E25: 3644 | F25: United States
A26: Funholding | B26: finance | C26: 1991 | D26: 2819.5 | E26: 7227 | F26: United States | G26: Golddex
A27: Ganjaflex | B27: retail | C27: 1995 | D27: 5158.71 | E27: 17479 | F27: Japan
A28: Gekko & Co | B28: retail | C28: 1990 | D28: 2520.83 | E28: 3502 | F28: United States
A29: Genco Pura Olive Oil Company | B29: retail | C29: 2007 | D29: 894.33 | E29: 1635 | F29: Italy
A30: Globex Corporation | B30: technolgy | C30: 2000 | D30: 1223.72 | E30: 2497 | F30: Norway
A31: Gogozoom | B31: telecommunications | C31: 2007 | D31: 86.68 | E31: 187 | F31: United States | G31: Sonron
A32: Golddex | B32: finance | C32: 2008 | D32: 52.5 | E32: 165 | F32: United States
A33: Goodsilron | B33: marketing | C33: 2000 | D33: 2952.73 | E33: 5107 | F33: United States
A34: Green-Plus | B34: services | C34: 2003 | D34: 692.19 | E34: 1922 | F34: United States
A35: Groovestreet | B35: retail | C35: 2003 | D35: 223.8 | E35: 299 | F35: United States
A36: Hatfan | B36: services | C36: 1982 | D36: 792.46 | E36: 1299 | F36: United States
A37: Hottechi | B37: technolgy | C37: 1997 | D37: 8170.38 | E37: 16499 | F37: Korea
A38: Initech | B38: telecommunications | C38: 1994 | D38: 6395.05 | E38: 20275 | F38: United States
A39: Inity | B39: marketing | C39: 1986 | D39: 2403.58 | E39: 8801 | F39: United States
A40: Isdom | B40: medical | C40: 2002 | D40: 3178.24 | E40: 4540 | F40: United States
...

Sheet products
A1: product | B1: series | C1: sales_price
A2: GTX Basic | B2: GTX | C2: 550
A3: GTX Pro | B3: GTX | C3: 4821
A4: MG Special | B4: MG | C4: 55
A5: MG Advanced | B5: MG | C5: 3393
A6: GTX Plus Pro | B6: GTX | C6: 5482
A7: GTX Plus Basic | B7: GTX | C7: 1096
A8: GTK 500 | B8: GTK | C8: 26768

Sheet Table Field Description
A1: Table | B1: Field | C1: Description
A2: accounts | B2: account | C2: Company name
A3: accounts | B3: sector | C3: Industry
A4: accounts | B4: year_established | C4: Year Established
A5: accounts | B5: revenue | C5: Annual revenue (in millions of USD)
A6: accounts | B6: employees | C6: Number of employees
A7: accounts | B7: office_location | C7: Headquarters
A8: accounts | B8: subsidiary_of | C8: Parent company
A9: products | B9: product | C9: Product name
A10: products | B10: series | C10: Product series
A11: products | B11: sales_price | C11: Suggested retail price
A12: sales_teams | B12: sales_agent | C12: Sales agent
... A22: sales_pipeline | B22: close_value | C22: Revenue from the deal

Sheet sales teams
A1: sales_agent | B1: manager | C1: regional_office
A2: Anna Snelling | B2: Dustin Brinkmann | C2: Central
A3: Cecily Lampkin | B3: Dustin Brinkmann | C3: Central
A4: Versie Hillebrand | B4: Dustin Brinkmann | C4: Central
A5: Lajuana Vencill | B5: Dustin Brinkmann | C5: Central
A6: Moses Frase | B6: Dustin Brinkmann | C6: Central
A7: Jonathan Berthelot | B7: Melvin Marxen | C7: Central
A8: Marty Freudenburg | B8: Melvin Marxen | C8: Central
A9: Gladys Colclough | B9: Melvin Marxen | C9: Central
A10: Niesha Huffines | B10: Melvin Marxen | C10: Central
A11: Darcel Schlecht | B11: Melvin Marxen | C11: Central
A12: Mei-Mei Johns | B12: Melvin Marxen | C12: Central
... A36: Carl Lin | B36: Summer Sewald | C36: West
